Workbook

Sheet Test Cases
A1: TC-ID | B1: Category | C1: Feature | D1: Test Case Title | E1: Preconditions | F1: Test Steps | G1: Expected Result | H1: Priority | I1: Implementation Status | J1: Notes | K1: URL | L1: Pass Status | M1: Link | N1: Notes | O1: Spec Ref
A2: TC-SUB-001 | B2: Submission | C2: Form Fields | D2: Submit ringi with all required fields | E2: User logged in as employee | F2: 1. Navigate to the app URL 2. Click 'New Submission' button 3. Fill in Title: 'Office Supplies Purchase' 4. Select Category: 'Purchasing' 5. Enter Vendor Name: 'ABC Corp' 6. Add item: Name='Printer', Qty=2, Amount=50000 7. Select Priority: 'High' 8. Set Required By Date 9. Enter Department: 'Engineering' 10. Enter Reason for Purchase 11. Enter Purpose 12. Click Submit | G2: Ringi created with status 'Pending'. Card appears in dashboard list. Activity log records the creation. | H2: P1 | I2: Implemented | J2: Core submission flow works with current form fields | K2: https://eb-filemg-development.vercel.app | L2: N/A | O2: Spec 6.1 (Submission) → "Form fields: Subject, Category (Purchasing, Contracts, Expenses, Misc.), Amount (tax incl./excl.), Tax category, Payment terms, Vendor/Counterparty, Purpose, Period, Budget code, Project, Desired approval date, Applicant/Department."
A3: TC-SUB-002 | B3: Submission | C3: Tax Calculation | D3: Submit ringi with tax-inclusive calculation | E3: User logged in, category is Purchasing | F3: 1. Click 'New Submission' 2. Select Category: 'Purchasing' 3. Toggle 'Use Tax' ON 4. Toggle 'Tax Included' 5. Enter Tax Rate: 10% 6. Add item: Amount=110000 7. Fill remaining required fields 8. Click Submit | G3: Tax calculated correctly. Amount displays with tax-inclusive label. Total reflects tax calculation. | H3: P2 | I3: Implemented | J3: Tax toggle only shows for Purchasing category | K3: https://eb-filemg-development.vercel.app | L3: N/A | O3: Spec 6.1 (Submission) → "Form fields: Subject, Category (Purchasing, Contracts, Expenses, Misc.), Amount (tax incl./excl.), Tax category, Payment terms, Vendor/Counterparty, Purpose, Period, Budget code, Project, Desired approval date, Applicant/Department."
A4: TC-SUB-003 | B4: Submission | C4: Tax Calculation | D4: Submit ringi with tax-exclusive calculation | E4: User logged in, category is Purchasing | F4: 1. Click 'New Submission' 2. Select Category: 'Purchasing' 3. Toggle 'Use Tax' ON 4. Toggle 'Tax Excluded' 5. Enter Tax Rate: 10% 6. Add item: Amount=100000 7. Fill remaining required fields 8. Click Submit | G4: Tax calculated on top of amount. Display shows tax-exclusive amount + tax = total. | H4: P2 | I4: Implemented | J4: Tax-exclusive adds tax on top of base amount | K4: https://eb-filemg-development.vercel.app | L4: N/A | O4: Spec 6.1 (Submission) → "Form fields: Subject, Category (Purchasing, Contracts, Expenses, Misc.), Amount (tax incl./excl.), Tax category, Payment terms, Vendor/Counterparty, Purpose, Period, Budget code, Project, Desired approval date, Applicant/Department."
A5: TC-SUB-004 | B5: Submission | C5: Line Items | D5: Submit ringi with multiple line items | E5: User logged in | F5: 1. Click 'New Submission' 2. Fill required fields 3. Add Item 1: 'Laptop', Qty=5, Amount=200000 4. Click 'Add Item' 5. Add Item 2: 'Mouse', Qty=5, Amount=5000 6. Click 'Add Item' 7. Add Item 3: 'Keyboard', Qty=5, Amount=8000 8. Verify total auto-calculates 9. Click Submit | G5: All 3 items saved. Total amount = (200000x5 + 5000x5 + 8000x5) = 1,065,000. Items table displays correctly on detail page. | H5: P2 | I5: Implemented | J5: Items stored as JSONB array | K5: https://eb-filemg-development.vercel.app | L5: N/A | O5: Spec 6.1 (Submission) → "Form fields: Subject, Category (Purchasing, Contracts, Expenses, Misc.), Amount (tax incl./excl.), Tax category, Payment terms, Vendor/Counterparty, Purpose, Period, Budget code, Project, Desired approval date, Applicant/Department."
A6: TC-SUB-005 | B6: Submission | C6: Validation | D6: Submit ringi with missing required fields | E6: User logged in | F6: 1. Click 'New Submission' 2. Leave Title empty 3. Leave Vendor Name empty 4. Do not add any items 5. Click Submit | G6: Form validation errors shown for all required fields. Submission is blocked. Error messages in current language (EN/JA). | H6: P1 | I6: Implemented | J6: Yup validation schema enforces required fields | K6: https://eb-filemg-development.vercel.app | L6: N/A | O6: Spec 6.1 (Submission) → "Form fields: Subject, Category (Purchasing, Contracts, Expenses, Misc.), Amount (tax incl./excl.), Tax category, Payment terms, Vendor/Counterparty, Purpose, Period, Budget code, Project, Desired approval date, Applicant/Department."
A7: TC-SUB-006 | B7: Submission | C7: Attachments | D7: Submit ringi with document attachments | E7: User logged in, documents exist in system | F7: 1. Click 'New Submission' 2. Fill all required fields 3. In attachments section, upload a PDF file 4. Upload a second image file 5. Click Submit 6. Navigate to detail page | G7: Both attachments linked to the ringi. File cards display on detail page with download links. | H7: P2 | I7: Implemented | J7: Uses approval_request_documents junction table | K7: https://eb-filemg-development.vercel.app | L7: N/A | O7: Spec 6.1 (Submission) → "Attachments: Quotes, contracts, and related materials. No tampering allowed after approval (must re-apply as a new version)."
A8: TC-SUB-008 | B8: Submission | C8: Form Fields | D8: Verify budget_code field exists in form | E8: User logged in | F8: 1. Click 'New Submission' 2. Look for 'Budget Code' field in the form 3. Enter a budget code value | G8: Budget Code field present and fillable. Value saved with ringi. | H8: P3 | I8: Not Yet Implemented | J8: Spec section 8 requires budget_code. Not in current schema. | K8: https://eb-filemg-development.vercel.app | L8: N/A | O8: Spec 6.1 (Submission) → "Form fields: Subject, Category (Purchasing, Contracts, Expenses, Misc.), Amount (tax incl./excl.), Tax category, Payment terms, Vendor/Counterparty, Purpose, Period, Budget code, Project, Desired approval date, Applicant/Department."
A9: TC-SUB-009 | B9: Submission | C9: Form Fields | D9: Verify project_code field exists in form | E9: User logged in | F9: 1. Click 'New Submission' 2. Look for 'Project Code' field in the form 3. Enter a project code value | G9: Project Code field present and fillable. Value saved with ringi. | H9: P3 | I9: Not Yet Implemented | J9: Spec section 8 requires project_code. Not in current schema. | K9: https://eb-filemg-development.vercel.app | L9: N/A | O9: Spec 6.1 (Submission) → "Form fields: Subject, Category (Purchasing, Contracts, Expenses, Misc.), Amount (tax incl./excl.), Tax category, Payment terms, Vendor/Counterparty, Purpose, Period, Budget code, Project, Desired approval date, Applicant/Department."
A10: TC-SUB-010 | B10: Submission | C10: Form Fields | D10: Verify currency field exists in form | E10: User logged in | F10: 1. Click 'New Submission' 2. Look for 'Currency' selector in the form 3. Select different currencies (JPY, USD, etc.) | G10: Currency field present with options (JPY, USD, etc.). Selected currency saved with ringi. | H10: P3 | I10: Not Yet Implemented | J10: Spec section 8 requires currency. Not in current schema. | K10: https://eb-filemg-development.vercel.app | L10: N/A | O10: Spec 6.1 (Submission) → "Form fields: Subject, Category (Purchasing, Contracts, Expenses, Misc.), Amount (tax incl./excl.), Tax category, Payment terms, Vendor/Counterparty, Purpose, Period, Budget code, Project, Desired approval date, Applicant/Department."
A11: TC-SUB-011 | B11: Submission | C11: Form Fields | D11: Verify start_date and end_date (period) fields | E11: User logged in | F11: 1. Click 'New Submission' 2. Look for 'Start Date' and 'End Date' (Period) fields 3. Set both dates | G11: Both start and end date fields present for period specification. Values saved. | H11: P3 | I11: Not Yet Implemented | J11: Current code has single 'date' field. Spec requires start_date and end_date. | K11: https://eb-filemg-development.vercel.app | L11: N/A | O11: Spec 6.1 (Submission) → "Form fields: Subject, Category (Purchasing, Contracts, Expenses, Misc.), Amount (tax incl./excl.), Tax category, Payment terms, Vendor/Counterparty, Purpose, Period, Budget code, Project, Desired approval date, Applicant/Department."
A12: TC-SUB-012 | B12: Submission | C12: Form Fields | D12: Verify desired_approval_date field | E12: User logged in | F12: 1. Click 'New Submission' 2. Look for 'Desired Approval Date' field 3. Select a date | G12: Desired approval date field present and selectable. Value saved with ringi. | H12: P3 | I12: Not Yet Implemented | J12: Spec section 8 requires desired_approval_date. Not in current schema. | K12: https://eb-filemg-development.vercel.app | L12: N/A | O12: Spec 6.1 (Submission) → "Form fields: Subject, Category (Purchasing, Contracts, Expenses, Misc.), Amount (tax incl./excl.), Tax category, Payment terms, Vendor/Counterparty, Purpose, Period, Budget code, Project, Desired approval date, Applicant/Department."
A13: TC-SUB-013 | B13: Submission | C13: Draft | D13: Save ringi as draft | E13: User logged in | F13: 1. Click 'New Submission' 2. Fill some fields partially 3. Click 'Save as Draft' 4. Verify status shows 'Draft' 5. Return later and edit the draft 6. Submit the draft | G13: Ringi saved with status 'Draft'. Appears in dashboard with Draft badge. Not visible to approvers. Can be edited and submitted later. | H13: P2 | I13: Not Yet Implemented | J13: No 'draft' status in current system. Spec requires Draft as initial state. | K13: https://eb-filemg-development.vercel.app | L13: N/A | O13: Spec 6.1 (Submission) → "Statuses: Draft / Applying / Waiting for Approval (by stage) / Sent Back / Rejected / Approved / Expired."
... A108: TC-PDF-003 | B108: PDF Generation | C108: S3 Storage | D108: Verify PDF stored in S3 with metadata tags | E108: Completion PDF generated | F108: 1. Check S3 bucket for generated PDF 2. Verify metadata tags applied (ringi_id, category, department, approved_date) 3. Verify S3 object key follows naming convention | G108: PDF stored in S3 with proper metadata tags. Accessible via presigned URL. | H108: P3 | I108: Not Yet Implemented | J108: No S3 metadata tagging for completion PDFs. | K108: https://eb-filemg-development.vercel.app | L108: N/A | O108: Spec 6.3 (Approval Operations) → "Completed Ringi PDF and attachments are stored in S3 with metadata."

Sheet Summary
A1: Test Cases — Spec Implementation Coverage
A2: Category | B2: Total | C2: Implemented | D2: Partial | E2: Not Yet | F2: Coverage %
A3: Submission | B3: =COUNTIF('Test Cases'!B:B,A3) | C3: =COUNTIFS('Test Cases'!B:B,A3,'Test Cases'!I:I,"Implemented") | D3: =COUNTIFS('Test Cases'!B:B,A3,'Test Cases'!I:I,"Partially Implemented") | E3: =B3-C3-D3 | F3: =IF(B3=0,0,(C3+D3*0.5)/B3)
A4: Approval Routes | B4: =COUNTIF('Test Cases'!B:B,A4) | C4: =COUNTIFS('Test Cases'!B:B,A4,'Test Cases'!I:I,"Implemented") | D4: =COUNTIFS('Test Cases'!B:B,A4,'Test Cases'!I:I,"Partially Implemented") | E4: =B4-C4-D4 | F4: =IF(B4=0,0,(C4+D4*0.5)/B4)
A5: Approval Operations | B5: =COUNTIF('Test Cases'!B:B,A5) | C5: =COUNTIFS('Test Cases'!B:B,A5,'Test Cases'!I:I,"Implemented") | D5: =COUNTIFS('Test Cases'!B:B,A5,'Test Cases'!I:I,"Partially Implemented") | E5: =B5-C5-D5 | F5: =IF(B5=0,0,(C5+D5*0.5)/B5)
A6: Notifications | B6: =COUNTIF('Test Cases'!B:B,A6) | C6: =COUNTIFS('Test Cases'!B:B,A6,'Test Cases'!I:I,"Implemented") | D6: =COUNTIFS('Test Cases'!B:B,A6,'Test Cases'!I:I,"Partially Implemented") | E6: =B6-C6-D6 | F6: =IF(B6=0,0,(C6+D6*0.5)/B6)
A7: Search & Reference | B7: =COUNTIF('Test Cases'!B:B,A7) | C7: =COUNTIFS('Test Cases'!B:B,A7,'Test Cases'!I:I,"Implemented") | D7: =COUNTIFS('Test Cases'!B:B,A7,'Test Cases'!I:I,"Partially Implemented") | E7: =B7-C7-D7 | F7: =IF(B7=0,0,(C7+D7*0.5)/B7)
A8: Reporting | B8: =COUNTIF('Test Cases'!B:B,A8) | C8: =COUNTIFS('Test Cases'!B:B,A8,'Test Cases'!I:I,"Implemented") | D8: =COUNTIFS('Test Cases'!B:B,A8,'Test Cases'!I:I,"Partially Implemented") | E8: =B8-C8-D8 | F8: =IF(B8=0,0,(C8+D8*0.5)/B8)
A9: Permissions & Security | B9: =COUNTIF('Test Cases'!B:B,A9) | C9: =COUNTIFS('Test Cases'!B:B,A9,'Test Cases'!I:I,"Implemented") | D9: =COUNTIFS('Test Cases'!B:B,A9,'Test Cases'!I:I,"Partially Implemented") | E9: =B9-C9-D9 | F9: =IF(B9=0,0,(C9+D9*0.5)/B9)
A10: UI/UX | B10: =COUNTIF('Test Cases'!B:B,A10) | C10: =COUNTIFS('Test Cases'!B:B,A10,'Test Cases'!I:I,"Implemented") | D10: =COUNTIFS('Test Cases'!B:B,A10,'Test Cases'!I:I,"Partially Implemented") | E10: =B10-C10-D10 | F10: =IF(B10=0,0,(C10+D10*0.5)/B10)
A11: Non-Functional | B11: =COUNTIF('Test Cases'!B:B,A11) | C11: =COUNTIFS('Test Cases'!B:B,A11,'Test Cases'!I:I,"Implemented") | D11: =COUNTIFS('Test Cases'!B:B,A11,'Test Cases'!I:I,"Partially Implemented") | E11: =B11-C11-D11 | F11: =IF(B11=0,0,(C11+D11*0.5)/B11)
A12: Admin & Operations | B12: =COUNTIF('Test Cases'!B:B,A12) | C12: =COUNTIFS('Test Cases'!B:B,A12,'Test Cases'!I:I,"Implemented") | D12: =COUNTIFS('Test Cases'!B:B,A12,'Test Cases'!I:I,"Partially Implemented") | E12: =B12-C12-D12 | F12: =IF(B12=0,0,(C12+D12*0.5)/B12)
A13: Data Model | B13: =COUNTIF('Test Cases'!B:B,A13) | C13: =COUNTIFS('Test Cases'!B:B,A13,'Test Cases'!I:I,"Implemented") | D13: =COUNTIFS('Test Cases'!B:B,A13,'Test Cases'!I:I,"Partially Implemented") | E13: =B13-C13-D13 | F13: =IF(B13=0,0,(C13+D13*0.5)/B13)
A14: PDF Generation | B14: =COUNTIF('Test Cases'!B:B,A14) | C14: =COUNTIFS('Test Cases'!B:B,A14,'Test Cases'!I:I,"Implemented") | D14: =COUNTIFS('Test Cases'!B:B,A14,'Test Cases'!I:I,"Partially Implemented") | E14: =B14-C14-D14 | F14: =IF(B14=0,0,(C14+D14*0.5)/B14)
A15: TOTAL | B15: =SUM(B3:B14) | C15: =SUM(C3:C14) | D15: =SUM(D3:D14) | E15: =SUM(E3:E14) | F15: =IF(B15=0,0,(C15+D15*0.5)/B15)
A17: Actionable Test Cases — QA Test Results
A18: Category | B18: Total | C18: Passed | D18: Partial Pass | E18: Failed | F18: Blocked | G18: Pass Rate %
A19: Submission | B19: =COUNTIF('Actionable Test Cases'!B:B,A19) | C19: =COUNTIFS('Actionable Test Cases'!B:B,A19,'Actionable Test Cases'!K:K,"Passed") | D19: =COUNTIFS('Actionable Test Cases'!B:B,A19,'Actionable Test Cases'!K:K,"Partial Pass") | E19: =COUNTIFS('Actionable Test Cases'!B:B,A19,'Actionable Test Cases'!K:K,"Failed") | F19: =COUNTIFS('Actionable Test Cases'!B:B,A19,'Actionable Test Cases'!K:K,"Blocked") | G19: =IF((B19-F19)=0,0,(C19+D19*0.5)/(B19-F19))
A20: Approval | B20: =COUNTIF('Actionable Test Cases'!B:B,A20) | C20: =COUNTIFS('Actionable Test Cases'!B:B,A20,'Actionable Test Cases'!K:K,"Passed") | D20: =COUNTIFS('Actionable Test Cases'!B:B,A20,'Actionable Test Cases'!K:K,"Partial Pass") | E20: =COUNTIFS('Actionable Test Cases'!B:B,A20,'Actionable Test Cases'!K:K,"Failed") | F20: =COUNTIFS('Actionable Test Cases'!B:B,A20,'Actionable Test Cases'!K:K,"Blocked") | G20: =IF((B20-F20)=0,0,(C20+D20*0.5)/(B20-F20))
A21: AI Chat | B21: =COUNTIF('Actionable Test Cases'!B:B,A21) | C21: =COUNTIFS('Actionable Test Cases'!B:B,A21,'Actionable Test Cases'!K:K,"Passed") | D21: =COUNTIFS('Actionable Test Cases'!B:B,A21,'Actionable Test Cases'!K:K,"Partial Pass") | E21: =COUNTIFS('Actionable Test Cases'!B:B,A21,'Actionable Test Cases'!K:K,"Failed") | F21: =COUNTIFS('Actionable Test Cases'!B:B,A21,'Actionable Test Cases'!K:K,"Blocked") | G21: =IF((B21-F21)=0,0,(C21+D21*0.5)/(B21-F21))
A22: AI Retrieval | B22: =COUNTIF('Actionable Test Cases'!B:B,A22) | C22: =COUNTIFS('Actionable Test Cases'!B:B,A22,'Actionable Test Cases'!K:K,"Passed") | D22: =COUNTIFS('Actionable Test Cases'!B:B,A22,'Actionable Test Cases'!K:K,"Partial Pass") | E22: =COUNTIFS('Actionable Test Cases'!B:B,A22,'Actionable Test Cases'!K:K,"Failed") | F22: =COUNTIFS('Actionable Test Cases'!B:B,A22,'Actionable Test Cases'!K:K,"Blocked") | G22: =IF((B22-F22)=0,0,(C22+D22*0.5)/(B22-F22))
A23: Status | B23: =COUNTIF('Actionable Test Cases'!B:B,A23) | C23: =COUNTIFS('Actionable Test Cases'!B:B,A23,'Actionable Test Cases'!K:K,"Passed") | D23: =COUNTIFS('Actionable Test Cases'!B:B,A23,'Actionable Test Cases'!K:K,"Partial Pass") | E23: =COUNTIFS('Actionable Test Cases'!B:B,A23,'Actionable Test Cases'!K:K,"Failed") | F23: =COUNTIFS('Actionable Test Cases'!B:B,A23,'Actionable Test Cases'!K:K,"Blocked") | G23: =IF((B23-F23)=0,0,(C23+D23*0.5)/(B23-F23))
A24: User Role | B24: =COUNTIF('Actionable Test Cases'!B:B,A24) | C24: =COUNTIFS('Actionable Test Cases'!B:B,A24,'Actionable Test Cases'!K:K,"Passed") | D24: =COUNTIFS('Actionable Test Cases'!B:B,A24,'Actionable Test Cases'!K:K,"Partial Pass") | E24: =COUNTIFS('Actionable Test Cases'!B:B,A24,'Actionable Test Cases'!K:K,"Failed") | F24: =COUNTIFS('Actionable Test Cases'!B:B,A24,'Actionable Test Cases'!K:K,"Blocked") | G24: =IF((B24-F24)=0,0,(C24+D24*0.5)/(B24-F24))
A25: TOTAL | B25: =SUM(B19:B24) | C25: =SUM(C19:C24) | D25: =SUM(D19:D24) | E25: =SUM(E19:E24) | F25: =SUM(F19:F24) | G25: =IF((B25-F25)=0,0,(C25+D25*0.5)/(B25-F25))
A27: Legend
A28: Test Cases Status:
A29: Implemented = feature fully built and working | Partially Implemented = some functionality exists but gaps remain | Not Yet Implemented = not started
A30: Coverage % = (Implemented + Partially Implemented × 0.5) / Total
A32: Actionable Test Cases Status:
A33: Passed = test passed | Partial Pass = partially working | Failed = test failed | Blocked = cannot test (dependency/prerequisite missing)
A34: Pass Rate % = (Passed + Partial Pass × 0.5) / (Total − Blocked)
A37: Actionable Test Bugs — Bug Summary
A38: Category | B38: Total | C38: Critical | D38: Major | E38: Minor | F38: Bug | G38: Enhancement
A39: Submission | B39: =COUNTIF('Actionable Test Bugs'!C:C,A39) | C39: =COUNTIFS('Actionable Test Bugs'!C:C,A39,'Actionable Test Bugs'!G:G,"Critical") | D39: =COUNTIFS('Actionable Test Bugs'!C:C,A39,'Actionable Test Bugs'!G:G,"Major") | E39: =COUNTIFS('Actionable Test Bugs'!C:C,A39,'Actionable Test Bugs'!G:G,"Minor") | F39: =COUNTIFS('Actionable Test Bugs'!C:C,A39,'Actionable Test Bugs'!F:F,"Bug") | G39: =COUNTIFS('Actionable Test Bugs'!C:C,A39,'Actionable Test Bugs'!F:F,"Enhancement")
A40: Approval | B40: =COUNTIF('Actionable Test Bugs'!C:C,A40) | C40: =COUNTIFS('Actionable Test Bugs'!C:C,A40,'Actionable Test Bugs'!G:G,"Critical") | D40: =COUNTIFS('Actionable Test Bugs'!C:C,A40,'Actionable Test Bugs'!G:G,"Major") | E40: =COUNTIFS('Actionable Test Bugs'!C:C,A40,'Actionable Test Bugs'!G:G,"Minor") | F40: =COUNTIFS('Actionable Test Bugs'!C:C,A40,'Actionable Test Bugs'!F:F,"Bug") | G40: =COUNTIFS('Actionable Test Bugs'!C:C,A40,'Actionable Test Bugs'!F:F,"Enhancement")
A41: AI Chat | B41: =COUNTIF('Actionable Test Bugs'!C:C,A41) | C41: =COUNTIFS('Actionable Test Bugs'!C:C,A41,'Actionable Test Bugs'!G:G,"Critical") | D41: =COUNTIFS('Actionable Test Bugs'!C:C,A41,'Actionable Test Bugs'!G:G,"Major") | E41: =COUNTIFS('Actionable Test Bugs'!C:C,A41,'Actionable Test Bugs'!G:G,"Minor") | F41: =COUNTIFS('Actionable Test Bugs'!C:C,A41,'Actionable Test Bugs'!F:F,"Bug") | G41: =COUNTIFS('Actionable Test Bugs'!C:C,A41,'Actionable Test Bugs'!F:F,"Enhancement")
A42: AI Retrieval | B42: =COUNTIF('Actionable Test Bugs'!C:C,A42) | C42: =COUNTIFS('Actionable Test Bugs'!C:C,A42,'Actionable Test Bugs'!G:G,"Critical") | D42: =COUNTIFS('Actionable Test Bugs'!C:C,A42,'Actionable Test Bugs'!G:G,"Major") | E42: =COUNTIFS('Actionable Test Bugs'!C:C,A42,'Actionable Test Bugs'!G:G,"Minor") | F42: =COUNTIFS('Actionable Test Bugs'!C:C,A42,'Actionable Test Bugs'!F:F,"Bug") | G42: =COUNTIFS('Actionable Test Bugs'!C:C,A42,'Actionable Test Bugs'!F:F,"Enhancement")
A43: Status | B43: =COUNTIF('Actionable Test Bugs'!C:C,A43) | C43: =COUNTIFS('Actionable Test Bugs'!C:C,A43,'Actionable Test Bugs'!G:G,"Critical") | D43: =COUNTIFS('Actionable Test Bugs'!C:C,A43,'Actionable Test Bugs'!G:G,"Major") | E43: =COUNTIFS('Actionable Test Bugs'!C:C,A43,'Actionable Test Bugs'!G:G,"Minor") | F43: =COUNTIFS('Actionable Test Bugs'!C:C,A43,'Actionable Test Bugs'!F:F,"Bug") | G43: =COUNTIFS('Actionable Test Bugs'!C:C,A43,'Actionable Test Bugs'!F:F,"Enhancement")
A44: User Role | B44: =COUNTIF('Actionable Test Bugs'!C:C,A44) | C44: =COUNTIFS('Actionable Test Bugs'!C:C,A44,'Actionable Test Bugs'!G:G,"Critical") | D44: =COUNTIFS('Actionable Test Bugs'!C:C,A44,'Actionable Test Bugs'!G:G,"Major") | E44: =COUNTIFS('Actionable Test Bugs'!C:C,A44,'Actionable Test Bugs'!G:G,"Minor") | F44: =COUNTIFS('Actionable Test Bugs'!C:C,A44,'Actionable Test Bugs'!F:F,"Bug") | G44: =COUNTIFS('Actionable Test Bugs'!C:C,A44,'Actionable Test Bugs'!F:F,"Enhancement")
A45: TOTAL | B45: =SUM(B39:B44) | C45: =SUM(C39:C44) | D45: =SUM(D39:D44) | E45: =SUM(E39:E44) | F45: =SUM(F39:F44) | G45: =SUM(G39:G44)

Sheet Actionable Test Cases
A1: TC-ID | B1: Category | C1: Feature | D1: Test Case Title | E1: Type | F1: Preconditions | G1: Test Steps | H1: Expected Result | I1: Test Files | J1: Priority | K1: Pass Status | L1: Link | M1: Notes | N1: Spec Ref
A2: KT-SUB-001 | B2: Submission | C2: Submit with valid EN doc | D2: Submit ringi with valid English document attachment | E2: Main | F2: Login as staff@gmail.com | G2: 1. Login staff@gmail.com at https://eb-filemg-development.vercel.app 2. Click 'New Submission' → Category: Purchasing 3. Title: 'Annual Software License Renewal', Priority: High, Dept: Sales 4. Add Item: 'Adobe CC Enterprise License' ×1, $12,500 5. Vendor: 'Adobe Inc.', Payment: 2026-03-15, Bank Transfer 6. Required by: 2026-03-01 09:00 7. Reason: 'Annual renewal of Adobe CC licenses, expires March 31' 8. Purpose: 'Maintain design tool access for Sales marketing' 9. Attach ringi_en_detailed_license_renewal.docx 10. Verify Approval Route → Click 'Create Submission' | H2: Submission created with 'Pending' status. Title='Annual Software License Renewal', Priority=High, Amount=$12,500. File attached and visible in detail view. Approval route displayed. | I2: ringi_en_detailed_license_renewal.docx | J2: P1 | K2: Passed | L2: https://jam.dev/c/c59ad198-fb75-4953-8e4c-279d811bdcc1 | M2: there is subtle bug: Submitted By Staff null --- It would be beneficial if there is Draft submission status as well | N2: Spec 6.1 (Submission) → "Form fields: Subject, Category (Purchasing, Contracts, Expenses, Misc.), Amount (tax incl./excl.), Tax category, Payment terms, Vendor/Counterparty, Purpose, Period, Budget code, Project, Desired approval date, Applicant/Department."
A3: KT-SUB-002 | B3: Submission | C3: Submit with valid JP doc | D3: Submit ringi with valid Japanese document attachment | E3: Main | F3: Login as staff@gmail.com | G3: 1. Login staff@gmail.com 2. New Submission → Category: Purchasing 3. Title: 'オフィスチェア購入稟議', Priority: Medium, Dept: 総務部 4. Add Item: 'エルゴノミクスオフィスチェア' ×10, ¥50,000 5. Enable Tax: ON, Rate: 10% 6. Vendor: 'オフィス家具株式会社', Payment: 2026-04-01, Bank Transfer 7. Required by: 2026-03-20 10:00 8. Reason: '総務部用オフィスチェア10脚の購入申請' 9. Purpose: '従業員の作業環境改善' 10. Attach ringi_jp_purchase_chairs.docx → Create Submission | H3: Submission created with JP content, no garbled text. Status 'Pending'. Tax: ¥500,000 + 10% = ¥550,000. File attached. | I3: ringi_jp_purchase_chairs.docx | J3: P1 | K3: Passed | L3: https://jam.dev/c/e7c5d836-7e67-4e76-82d7-9d8f3957ce0d | M3: there is subtle bug regarding the tax number in form and also in details | N3: Spec 6.1 (Submission) → "Form fields: Subject, Category (Purchasing, Contracts, Expenses, Misc.), Amount (tax incl./excl.), Tax category, Payment terms, Vendor/Counterparty, Purpose, Period, Budget code, Project, Desired approval date, Applicant/Department."
A4: KT-SUB-003 | B4: Submission | C4: Submit with all fields + line items | D4: Submit with all fields filled and multiple line items | E4: Main | F4: Login as staff@gmail.com | G4: 1. Login staff@gmail.com 2. New Submission → Category: Purchasing 3. Title: 'Dell 4K Monitor Purchase for Development Team', Priority: Medium, Dept: IT 4. Add Item 1: 'Dell UltraSharp U2723QE 27"' ×5, $750 5. Add Item 2: 'Monitor Stand Arm' ×5, $0 6. Vendor: 'Dell Technologies', Payment: 2026-04-15, Credit Card 7. Required by: 2026-04-01 14:00 8. Reason: 'Purchase 5x 4K monitors for dev team' 9. Purpose: 'Improve developer productivity with high-res displays' 10. Remarks: 'Deliver to Building A, Floor 3' 11. Attach ringi_en_purchase_monitors.docx → Create Submission | H4: All fields saved. Both line items visible (monitors + stands). Amount=$3,750. Attachment visible and downloadable. Status 'Pending'. | I4: ringi_en_purchase_monitors.docx | J4: P1 | K4: Passed | L4: https://jam.dev/c/e5777a3f-6626-4419-92d8-8884a9ef544d | M4: there is bug in detail when clicked the filed it show xml file | N4: Spec 6.1 (Submission) → "Form fields: Subject, Category (Purchasing, Contracts, Expenses, Misc.), Amount (tax incl./excl.), Tax category, Payment terms, Vendor/Counterparty, Purpose, Period, Budget code, Project, Desired approval date, Applicant/Department."
A5: KT-SUB-004 | B5: Submission | C5: Submit minimum fields | D5: Submit with minimum required fields only | E5: Basic | F5: Login as staff@gmail.com | G5: 1. Login staff@gmail.com 2. New Submission → Category: Other 3. Title: 'Minimum Fields Test', Priority: Low, Dept: General 4. No items, no attachment, no remarks 5. Vendor: 'N/A', Payment: 2026-05-01, Cash 6. Required by: 2026-04-30 17:00 7. Reason: 'Testing minimum required fields' 8. Purpose: 'QA Test' 9. Click 'Create Submission' | H5: Submission created with only required data. No validation errors on optional fields. Status 'Pending' on dashboard. | I5: (none) | J5: P2 | K5: Passed | L5: https://jam.dev/c/ca785d03-1021-4e40-987f-54b86a4660ea | N5: Spec 6.1 (Submission) → "Form fields: Subject, Category (Purchasing, Contracts, Expenses, Misc.), Amount (tax incl./excl.), Tax category, Payment terms, Vendor/Counterparty, Purpose, Period, Budget code, Project, Desired approval date, Applicant/Department."
A6: KT-SUB-005 | B6: Submission | C6: Submit with Excel attachment | D6: Submit with Excel spreadsheet ringi attachment | E6: Basic | F6: Login as staff@gmail.com | G6: 1. Login staff@gmail.com 2. New Submission → Category: Expense 3. Title: '会計ソフト更新', Priority: Medium, Dept: 経理部 4. Add Item: 'freee会計 年間ライセンス' ×1, ¥600,000 5. Vendor: 'freee株式会社', Payment: 2026-04-01, Bank Transfer 6. Required by: 2026-03-25 10:00 7. Reason: '経理部の会計ソフトfreeeの年間ライセンス更新' 8. Purpose: '経理業務の継続' 9. Attach ringi_jp_spreadsheet_accounting.xlsx → Create Submission | H6: Excel file (.xlsx) accepted as attachment. Submission created. File downloadable from detail view. | I6: ringi_jp_spreadsheet_accounting.xlsx | J6: P2 | K6: Passed | L6: https://jam.dev/c/5a4cb745-883b-45d7-9be7-dfc259942d1f | N6: Spec 6.1 (Submission) → "Attachments: Quotes, contracts, and related materials. No tampering allowed after approval (must re-apply as a new version)."
A7: KT-SUB-006 | B7: Submission | C7: Edit pending submission | D7: Edit an existing pending submission | E7: Basic | F7: Existing pending submission by staff@gmail.com | G7: 1. Login staff@gmail.com 2. Go to dashboard, click pending submission card → detail /approval-requests/[id] 3. Click Edit 4. Change title to 'Updated: [original title]' 5. Change Priority to Critical 6. Save changes | H7: Edit form loads with pre-filled data. Changes saved. Submission remains 'Pending'. Updated values visible in detail. | I7: (none) | J7: P2 | K7: Passed | L7: https://jam.dev/c/d10f06f9-6592-48b7-bdd6-b8f727a38b55 | N7: Spec 6.1 (Submission) → "Statuses: Draft / Applying / Waiting for Approval (by stage) / Sent Back / Rejected / Approved / Expired."
A8: KT-SUB-007 | B8: Submission | C8: Submit with image file | D8: Submit with beach image as attachment (wrong file type) | E8: Edge Case | F8: Login as staff@gmail.com | G8: 1. Login staff@gmail.com 2. New Submission → Category: Other 3. Title: 'Edge Case Test - Image Upload', Priority: Low, Dept: QA 4. Vendor: 'Test', Payment: 2026-05-01, Cash 5. Required by: 2026-04-30 17:00 6. Reason: 'Testing image file upload behavior', Purpose: 'QA Edge Case' 7. Attach edge_beach_image.jpg 8. Attempt to submit | H8: System either rejects image file type with clear message, or accepts gracefully (no crash, no corrupt data). | I8: edge_beach_image.jpg | J8: P2 | K8: Passed | L8: https://jam.dev/c/9809373a-1afa-4a8d-8540-e4836b18b2c5 | N8: Spec 6.1 (Submission) → "Attachments: Quotes, contracts, and related materials. No tampering allowed after approval (must re-apply as a new version)."
A9: KT-SUB-008 | B9: Submission | C9: Submit with empty PDF | D9: Submit with empty/blank PDF attachment | E9: Edge Case | F9: Login as staff@gmail.com | G9: 1. Login staff@gmail.com 2. New Submission → Category: Other 3. Title: 'Edge Case Test - Empty PDF', Priority: Low, Dept: QA 4. Vendor: 'Test', Payment: 2026-05-01, Cash 5. Required by: 2026-04-30 17:00 6. Reason: 'Testing empty PDF upload behavior', Purpose: 'QA Edge Case' 7. Attach edge_empty_file.pdf (blank PDF) 8. Click 'Create Submission' | H9: System handles blank PDF without crashing. Either accepts or shows appropriate warning. | I9: edge_empty_file.pdf | J9: P3 | K9: Passed | L9: https://jam.dev/c/22a8a004-c862-44b8-9dbf-5c70b1825501 | N9: Spec 6.1 (Submission) → "Attachments: Quotes, contracts, and related materials. No tampering allowed after approval (must re-apply as a new version)."
A10: KT-SUB-009 | B10: Submission | C10: Submit with special chars filename | D10: Submit with Japanese characters in filename | E10: Edge Case | F10: Login as staff@gmail.com | G10: 1. Login staff@gmail.com 2. New Submission → Category: Other 3. Title: 'Edge Case Test - Special Characters', Priority: Low, Dept: QA 4. Vendor: 'Test', Payment: 2026-05-01, Cash 5. Required by: 2026-04-30 17:00 6. Reason: 'Testing special character filename handling', Purpose: 'QA Edge Case' 7. Attach edge_special_chars_名前.docx (JP chars in filename) 8. Click 'Create Submission' | H10: File uploaded. Japanese characters in filename preserved and displayed correctly. Submission created without errors. | I10: edge_special_chars_名前.docx | J10: P2 | K10: Failed | L10: https://jam.dev/c/e9e24876-69bd-4c41-ba8b-0886be4cd867 | M10: error file char name | N10: Spec 6.1 (Submission) → "Attachments: Quotes, contracts, and related materials. No tampering allowed after approval (must re-apply as a new version)."
A11: KT-SUB-010 | B11: Submission | C11: Submit with very large amount | D11: Submit with extremely large amount value | E11: Edge Case | F11: Login as staff@gmail.com | G11: 1. Login staff@gmail.com 2. New Submission → Category: Other 3. Title: 'Edge Case Test - Large Amount', Priority: Low, Dept: QA 4. Add Item: 'Large Amount Test Item' ×1, $999,999,999,999 5. Vendor: 'Test', Payment: 2026-05-01, Cash 6. Required by: 2026-04-30 17:00 7. Reason: 'Testing large amount handling', Purpose: 'QA Edge Case' 8. Click 'Create Submission' | H11: System either accepts the large number or shows validation for max amount. No crash or data corruption. | I11: (none) | J11: P3 | K11: Failed | L11: https://jam.dev/c/e7cb4064-6b39-4b65-a1e8-e609eef7f6e5 | M11: number overflow | N11: Spec 6.1 (Submission) → "Form fields: Subject, Category (Purchasing, Contracts, Expenses, Misc.), Amount (tax incl./excl.), Tax category, Payment terms, Vendor/Counterparty, Purpose, Period, Budget code, Project, Desired approval date, Applicant/Department."
A12: KT-APR-001 | B12: Approval | C12: Manager approves ringi | D12: Manager approves a pending ringi submission | E12: Main | F12: Pending submission exists (submitted by staff) | G12: 1. Login manager@gmail.com at https://eb-filemg-development.vercel.app 2. Find pending ringi card on dashboard 3. Click card → detail /approval-requests/[id] 4. Review Details tab, then Files tab 5. Click green Approve button 6. (Optional) Notes: 'Approved - budget within Q1 allocation' 7. Click Confirm 8. Switch to staff@gmail.com → verify 'Approved' on dashboard | H12: Status changes to 'Approved'. Recorded with timestamp in Timeline tab. Green CheckCircle icon. Staff sees 'Approved'. | I12: (none) | J12: P1 | K12: Failed | L12: https://jam.dev/c/432754ce-879c-4937-a5a1-f315125385af | M12: There is glitch of approval with status and then it is empty (but there is workaround to login as staff first and then logout and then login as manager) | N12: Spec 6.3 (Approval Operations) → "Statuses: Draft / Applying / Waiting for Approval (by stage) / Sent Back / Rejected / Approved / Expired."
A13: KT-APR-002 | B13: Approval | C13: Manager rejects with reason | D13: Manager rejects ringi with rejection reason | E13: Main | F13: Pending submission exists | G13: 1. Login manager@gmail.com 2. Find pending ringi → detail /approval-requests/[id] 3. Click red Reject button 4. Try submitting without reason → verify validation error 5. Enter: 'Budget exceeded for Q1. Please reduce or defer to Q2.' 6. Click Confirm | H13: Validation error when no reason. Status → 'Rejected' with XCircle icon. Reason in Timeline tab. Staff sees rejection reason. | I13: (none) | J13: P1 | K13: Blocked | L13: blocked of the KT-APR-001 | N13: Spec 6.3 (Approval Operations) → "Reason comments are mandatory for send-backs and rejections. Difference notes for re-applications."
A14: KT-APR-003 | B14: Approval | C14: Manager requests revision | D14: Manager sends back ringi for revision | E14: Basic | F14: Pending submission exists | G14: 1. Login manager@gmail.com 2. Open pending ringi detail /approval-requests/[id] 3. Click 'Request Revision' / 'Send Back' 4. Enter: 'Please add detailed cost breakdown and attach vendor quotation.' 5. Click Confirm | H14: Status → 'Need Revision'. Feedback saved in Timeline tab. Staff sees feedback and edit option. | I14: (none) | J14: P2 | K14: Blocked | L14: blocked of the KT-APR-001 | N14: Spec 6.3 (Approval Operations) → "Reason comments are mandatory for send-backs and rejections. Difference notes for re-applications."
A15: KT-APR-004 | B15: Approval | C15: Staff re-edits after revision | D15: Staff edits and resubmits after revision request | E15: Basic | F15: Submission with "Need Revision" status | G15: 1. Login staff@gmail.com 2. Find 'Need Revision' submission on dashboard 3. Open detail /approval-requests/[id] → Click Edit 4. Update Reason with cost breakdown, adjust amount/items 5. Click Re-submit / Save | H15: Edit form loads with pre-filled data. Changes saved. Status returns to 'Pending' for manager re-review. | I15: (none) | J15: P2 | K15: Blocked | L15: blocked of the KT-APR-001 | N15: Spec 6.3 (Approval Operations) → "Reason comments are mandatory for send-backs and rejections. Difference notes for re-applications."
A16: KT-APR-005 | B16: Approval | C16: Staff blocked from approving | D16: Staff tries to approve a submission (should be blocked) | E16: Edge Case | F16: Pending submission exists | G16: 1. Login staff@gmail.com 2. Open pending submission detail /approval-requests/[id] 3. Inspect ALL action buttons on the page | H16: No Approve, Reject, or Request Revision buttons visible. Staff can only view details, files, and timeline. | I16: (none) | J16: P1 | K16: Passed | L16: https://jam.dev/c/ee692561-c9db-4fc1-9f6c-a9befb6953f0 | N16: Spec 6.7 (Permissions & Security) → "RBAC: Initiators edit/view their own applications, approvers operate on assigned cases, admins view all and change settings."
A17: KT-APR-006 | B17: Approval | C17: Double-approve attempt | D17: Attempt to approve an already-approved ringi | E17: Edge Case | F17: Already approved submission | G17: 1. Login manager@gmail.com 2. Open already-approved submission /approval-requests/[id] 3. Check if Approve/Reject buttons are still available | H17: Approve/Reject buttons NOT available for already-approved submissions. 'Approved' with green CheckCircle. No further actions. | I17: (none) | J17: P3 | K17: Blocked | N17: Spec 6.3 (Approval Operations) → "Statuses: Draft / Applying / Waiting for Approval (by stage) / Sent Back / Rejected / Approved / Expired."
A18: KT-APR-007 | B18: Approval | C18: Manager self-approval | D18: Manager tries to approve own submission | E18: Edge Case | F18: Manager has submitted own ringi | G18: 1. Login manager@gmail.com 2. New Submission → Category: Other 3. Title: 'Manager Self-Approval Test', Priority: Low, Dept: Management 4. Vendor: 'Internal', Payment: 2026-05-01, Cash 5. Required by: 2026-04-30 17:00 6. Reason: 'Testing self-approval behavior', Purpose: 'QA Test' 7. After submission, open own submission detail 8. Try to approve own submission | H18: Document actual behavior: self-approval allowed or blocked? If blocked: clear error. If allowed: processes normally. | I18: (none) | J18: P2 | K18: Passed | L18: https://jam.dev/c/af2dced4-d706-4673-ac8d-6723520dce0f | M18: Clarify the Requirement | N18: Spec 6.3 (Approval Operations) → "RBAC: Initiators edit/view their own applications, approvers operate on assigned cases, admins view all and change settings."
A19: KT-APR-008 | B19: Approval | C19: Quick-approve from dashboard | D19: Manager uses quick-approve action from card | E19: Basic | F19: Pending submissions visible on dashboard | G19: 1. Login manager@gmail.com 2. Go to dashboard 3. Find pending ringi card 4. Look for quick-approve action on card itself 5. If available, use quick-approve without opening detail | H19: Quick-approve action available on cards (if implemented). Approval succeeds from dashboard. Status updates immediately. | I19: (none) | J19: P2 | K19: Passed | N19: Spec 6.4 (Chat Integration), Spec 9 (UI/UX) → "Approve/send back from chat cards."
A20: KT-AIC-001 | B20: AI Chat | C20: Create ringi via AI (EN) | D20: Ask AI to create ringi from natural language in English | E20: Main | F20: Login as staff@gmail.com | G20: 1. Login staff@gmail.com 2. Go to https://eb-filemg-development.vercel.app/ (new chat) 3. Type: "Create a ringi for purchasing 10 office laptops, total cost $15,000" 4. Send and wait for AI response | H20: AI generates ringi draft with title, description, amount ($15,000). Response in English. Chat thread created (/c/[threadId]). | I20: (none) | J20: P1 | K20: Partial Pass | L20: https://jam.dev/c/3ff23937-7197-4d13-9381-65ef837e3113 | M20: AI generate pending, but not Draft it lead to user cannot edit the ringi when use try to edit the ringi, it got bugs | N20: Spec 5 (Business Flow), Spec 6.1, Spec 6.4 → "Initiator opens the Ringi initiation form via chat, enters required items and attachments, and submits."
A21: KT-AIC-002 | B21: AI Chat | C21: Create ringi via AI (JP) | D21: Ask AI to create ringi from natural language in Japanese | E21: Main | F21: Login as staff@gmail.com | G21: 1. Login staff@gmail.com 2. Go to new chat at / 3. Type: "ノートPC10台購入の稟議書を作成してください。合計金額150万円" 4. Send and wait for AI response | H21: AI generates ringi draft in Japanese with appropriate title and amount (¥1,500,000 / 150万円). | I21: (none) | J21: P1 | K21: Partial Pass | L21: https://jam.dev/c/37d7d204-3527-4e40-aad0-e51fab33d42a | M21: AI generate pending, but not Draft it lead to user cannot edit the ringi it got asking again and again same things | N21: Spec 5 (Business Flow), Spec 6.1, Spec 6.4 → "Initiator opens the Ringi initiation form via chat, enters required items and attachments, and submits."
A22: KT-AIC-003 | B22: AI Chat | C22: Upload doc + AI summarize | D22: Upload ringi doc and ask AI to summarize | E22: Basic | F22: Login as staff@gmail.com | G22: 1. Login staff@gmail.com 2. Go to new chat at / 3. Click paperclip → select ringi_en_detailed_license_renewal.docx 4. Verify file appears as attachment preview 5. Type: "Please summarize this ringi document" 6. Send and wait for response | H22: AI processes document. Summary mentions Adobe CC / license renewal, $12,500, Sales dept or Hanako Suzuki. Accurate to content. | I22: ringi_en_detailed_license_renewal.docx | J22: P1 | K22: Passed | L22: https://jam.dev/c/d1706ed5-abf0-4a53-b19d-a1368e703521 | N22: Spec 6.1, Spec 6.4 (Chat Integration) → "Contextual input assistance: Summarize chat messages to suggest initial form values."
A23: KT-AIC-004 | B23: AI Chat | C23: Ask about doc in Japanese | D23: Ask AI about uploaded document in Japanese | E23: Basic | F23: Login as staff@gmail.com | G23: 1. Login staff@gmail.com 2. Go to new chat at / 3. Click paperclip → select ringi_jp_standard_salesforce.docx 4. Type: "この稟議書の内容を教えてください" 5. Send and review response | H23: AI responds in Japanese. Summary mentions Salesforce / 営業支援ツール, ¥4,100,000, 営業部 or 鈴木花子. | I23: ringi_jp_standard_salesforce.docx | J23: P2 | K23: Passed | L23: https://jam.dev/c/40723d7b-aae3-47e5-81e3-d83304091945 | M23: there is UI glitch, also the loader is not appeared | N23: Spec 6.1, Spec 6.4 (Chat Integration) → "Contextual input assistance: Summarize chat messages to suggest initial form values."
A24: KT-AIC-005 | B24: AI Chat | C24: Upload image for ringi | D24: Upload beach image and ask AI to create ringi from it | E24: Edge Case | F24: Login as staff@gmail.com | G24: 1. Login staff@gmail.com 2. Go to new chat at / 3. Click paperclip → select edge_beach_image.jpg (beach photo) 4. Type: "Create a ringi from this document" 5. Send and review response | H24: AI does not crash. Indicates file is not a valid ringi document or cannot extract info from image. Graceful response. | I24: edge_beach_image.jpg | J24: P2 | K24: Passed | L24: https://jam.dev/c/f573209c-c362-421e-8cb7-e5367245fd4a | N24: Spec 6.1, Spec 6.4 (Chat Integration) → "Attachments: Quotes, contracts, and related materials. No tampering allowed after approval (must re-apply as a new version)."
A25: KT-AIC-006 | B25: AI Chat | C25: Gibberish/unrelated question | D25: Ask AI gibberish or unrelated question | E25: Edge Case | F25: Login as staff@gmail.com | G25: 1. Login staff@gmail.com 2. Go to new chat at / 3. Type: "asdfghjkl what is the weather today?" 4. Send and review response | H25: AI responds without crashing. Redirects to ringi-related help or provides polite response about scope. | I25: (none) | J25: P3 | K25: Passed | L25: https://jam.dev/c/aea773c3-1e12-4378-9647-a6ae532b19d8 | N25: Spec 6.4 (Chat Integration) → "Contextual input assistance: Summarize chat messages to suggest initial form values."
A26: KT-AIC-007 | B26: AI Chat | C26: Non-ringi doc for submission | D26: Upload non-ringi document and ask to create submission | E26: Edge Case | F26: Login as staff@gmail.com | G26: 1. Login staff@gmail.com 2. Go to new chat at / 3. Click paperclip → select edge_large_file.pdf (non-ringi content) 4. Type: "Create a ringi submission from this" 5. Send and review response | H26: AI processes document. Either extracts whatever info possible or indicates no ringi data. Graceful response. | I26: edge_large_file.pdf | J26: P2 | K26: Passed | L26: https://jam.dev/c/fa7689ce-95ec-4753-9c3c-7150f4b6a62a | N26: Spec 6.1, Spec 6.4 (Chat Integration) → "Contextual input assistance: Summarize chat messages to suggest initial form values."
A27: KT-AIC-008 | B27: AI Chat | C27: Multi-turn conversation | D27: Multi-turn conversation to build ringi incrementally | E27: Basic | F27: Login as staff@gmail.com | G27: 1. Login staff@gmail.com 2. Go to new chat at / 3. Msg 1: "I need to create a ringi for purchasing new office furniture" 4. Wait for response 5. Msg 2: "The budget is $8,000 for 10 standing desks from IKEA" 6. Wait for response 7. Msg 3: "Please finalize with department 'Operations' and requestor 'John Smith'" 8. Review final output | H27: AI maintains context across 3 turns. Final ringi: furniture, $8,000, 10 standing desks, IKEA, Operations, John Smith. Same thread URL. | I27: (none) | J27: P2 | K27: Partial Pass | L27: https://jam.dev/c/3517856c-1367-41bc-af8b-43a0a096d508 | M27: should comply with minimum required fields | N27: Spec 5 (Business Flow), Spec 6.4 → "Initiator opens the Ringi initiation form via chat, enters required items and attachments, and submits."
A28: KT-AIR-001 | B28: AI Retrieval | C28: Ask submission status (EN) | D28: Ask AI for status of specific submission in English | E28: Main | F28: Staff has existing submissions | G28: 1. Login staff@gmail.com (has existing submissions) 2. Note title of existing submission (e.g., 'Annual Software License Renewal') 3. Go to new chat at / 4. Type: "What is the status of 'Annual Software License Renewal'?" 5. Send and review response | H28: AI retrieves correct submission. Reports current status (Pending/Approved/etc.). Info matches dashboard. SearchResultsCard may display. | I28: (none) | J28: P1 | K28: Partial Pass | L28: https://jam.dev/c/6dfb78f5-bb0d-4d70-a03a-929b74ae0e49 | M28: it show the correct summary, yet files shown pending submssion are too manies | N28: Spec 6.5 (Search & Reference) → "Search/filter by Ringi ID, subject, applicant, department, amount range, status, and period."
A29: KT-AIR-002 | B29: AI Retrieval | C29: Find document by name | D29: Ask AI to find/retrieve a specific document by name | E29: Main | F29: Documents exist in system | G29: 1. Login staff@gmail.com 2. Go to new chat at / 3. Type: "Find the document called 'Dell 4K Monitor Purchase for Development Team'" 4. Send and review response | H29: AI locates submission. Provides status, date, amount info. SearchResultsCard with file card(s) and Open/Share buttons. | I29: (none) | J29: P1 | K29: Failed | L29: https://jam.dev/c/07e3abd6-675a-4cbd-b172-39321f9f55ec | M29: search about monitor yet not shown | N29: Spec 6.5 (Search & Reference) → "Search/filter by Ringi ID, subject, applicant, department, amount range, status, and period."
A30: KT-AIR-003 | B30: AI Retrieval | C30: Review submission status | D30: Ask AI to review and check submission status | E30: Basic | F30: Staff has submissions | G30: 1. Login staff@gmail.com (has multiple submissions) 2. Go to new chat at / 3. Type: "Review and check my submission status" 4. Send and review response | H30: AI lists staff's submissions with current statuses. List matches dashboard at /. | I30: (none) | J30: P2 | K30: Passed | L30: https://jam.dev/c/d1931bae-8fb2-47b1-81f8-e6b126a3675b | M30: but should be have pagination like to avoid long time, if many files also the numbering shown always 1 (which is bug) | N30: Spec 6.5 (Search & Reference) → "Search/filter by Ringi ID, subject, applicant, department, amount range, status, and period."
A31: KT-AIR-004 | B31: AI Retrieval | C31: Search in Japanese | D31: Search for document/status in Japanese | E31: Basic | F31: JP documents exist | G31: 1. Login staff@gmail.com (JP submissions exist) 2. Go to new chat at / 3. Type: "稟議書の状態を確認してください" 4. Send and review response | H31: AI responds in Japanese. Lists submissions with statuses. Japanese titles displayed correctly. | I31: (none) | J31: P2 | K31: Passed | L31: https://jam.dev/c/c2455701-1403-4615-9574-15a0ea25ec9c | M31: pass yet buggy, 1st submit waiting so long, the sent message is not disabled thus can prompt 2 times, and the response appear two times | N31: Spec 6.5 (Search & Reference) → "Search/filter by Ringi ID, subject, applicant, department, amount range, status, and period."
A32: KT-AIR-005 | B32: AI Retrieval | C32: Non-existent document | D32: Ask for non-existent document/submission | E32: Edge Case | F32: Login as staff@gmail.com | G32: 1. Login staff@gmail.com 2. Go to new chat at / 3. Type: "What is the status of ringi XYZ-NONEXISTENT-999?" 4. Send and review response | H32: AI does NOT return fabricated data. Indicates no matching submission found. Suggests checking title or listing existing. | I32: (none) | J32: P2 | K32: Passed | L32: https://jam.dev/c/b6fabc61-818c-473a-b6b5-d1a8bd6b611a | M32: Pass yet buggy, it give all pending requests | N32: Spec 6.5 (Search & Reference) → "Search/filter by Ringi ID, subject, applicant, department, amount range, status, and period."
A33: KT-AIR-006 | B33: AI Retrieval | C33: Another user's submission | D33: Ask for another user's submission status | E33: Edge Case | F33: Multiple users have submissions | G33: 1. Login staff@gmail.com 2. Go to new chat at / 3. Type: "What is the status of 'Manager Self-Approval Test'?" (manager's submission) 4. Send and review response | H33: AI respects data boundaries. Either denies access, shows limited info, or indicates another user's submission. | I33: (none) | J33: P2 | K33: Partial Pass | L33: https://jam.dev/c/af3d194a-5853-473f-87f7-df2e469fe7c3 | M33: It did not show yet the AI hallucinate | N33: Spec 6.5, Spec 6.7 (Permissions) → "RBAC: Initiators edit/view their own applications, approvers operate on assigned cases, admins view all and change settings."
A34: KT-STS-001 | B34: Status | C34: Pending status display | D34: Verify pending status display on card and detail | E34: Main | F34: Fresh submission just created | G34: 1. Login staff@gmail.com 2. New Submission → Category: Other 3. Title: 'Status Test - Pending', Priority: Low, Dept: QA 4. Vendor: 'Test', Payment: 2026-05-01, Cash 5. Required by: 2026-04-30 17:00 6. Reason: 'Testing pending status display', Purpose: 'QA Status Test' 7. After submission, find card on dashboard 8. Click card → detail view | H34: 'Pending' badge with orange styling on dashboard card and detail view. Submission in active list. | I34: (none) | J34: P1 | K34: Passed | L34: same as previous | N34: Spec 6.3, Spec 9 (UI/UX) → "Statuses: Draft / Applying / Waiting for Approval (by stage) / Sent Back / Rejected / Approved / Expired."
A35: KT-STS-002 | B35: Status | C35: Approved status display | D35: Verify approved status after manager approval | E35: Main | F35: Manager approves a submission | G35: 1. Login manager@gmail.com 2. Find 'Status Test - Pending' card → detail /approval-requests/[id] 3. Click green Approve → Confirm 4. Switch to staff@gmail.com 5. Find now-approved card on dashboard 6. Click → detail view | H35: 'Approved' badge with green color and CheckCircle icon on card and detail. Approval info in Timeline tab. | I35: (none) | J35: P1 | K35: Passed | N35: Spec 6.3, Spec 9 (UI/UX) → "Statuses: Draft / Applying / Waiting for Approval (by stage) / Sent Back / Rejected / Approved / Expired."
A36: KT-STS-003 | B36: Status | C36: Rejected status display | D36: Verify rejected status display | E36: Basic | F36: Manager rejects a submission | G36: 1. Login staff@gmail.com → New Submission: 'Status Test - To Be Rejected', Low, QA (fill remaining) 2. Switch to manager@gmail.com → find submission, open detail 3. Click red Reject → enter 'Test rejection' → Confirm 4. Switch to staff@gmail.com → view on dashboard and detail | H36: 'Rejected' badge with red color and XCircle icon. Rejection reason 'Test rejection' visible in Timeline tab. | I36: (none) | J36: P2 | K36: Passed | L36: https://jam.dev/c/2b43d3c6-f2ad-4a1d-984e-ee7d4b8bd278 | N36: Spec 6.3, Spec 9 (UI/UX) → "Statuses: Draft / Applying / Waiting for Approval (by stage) / Sent Back / Rejected / Approved / Expired."
A37: KT-STS-004 | B37: Status | C37: Need revision status display | D37: Verify need_revision status display | E37: Basic | F37: Manager requests revision | G37: 1. Login staff@gmail.com → New Submission: 'Status Test - Needs Revision', Low, QA (fill remaining) 2. Switch to manager@gmail.com → find submission, open detail 3. Click 'Request Revision' → enter 'Please add more details about the budget' → Confirm 4. Switch to staff@gmail.com → view on dashboard and detail | H37: 'Need Revision' badge with orange/yellow styling. Manager's feedback in Timeline tab. Edit button available for staff. | I37: (none) | J37: P2 | K37: Failed | M37: Not implemented? | N37: Spec 6.3, Spec 9 (UI/UX) → "Statuses: Draft / Applying / Waiting for Approval (by stage) / Sent Back / Rejected / Approved / Expired."
A38: KT-STS-005 | B38: Status | C38: Cancelled status display | D38: Verify cancelled status after owner cancels | E38: Basic | F38: Staff cancels own submission | G38: 1. Login staff@gmail.com → New Submission: 'Status Test - To Be Cancelled', Low, QA (fill remaining) 2. Find pending submission on dashboard → detail /approval-requests/[id] 3. Click Cancel (or equivalent withdraw action) 4. Verify status on dashboard and detail | H38: 'Cancelled' badge with grey styling. Submission no longer in active/pending lists. No further actions available. | I38: (none) | J38: P2 | K38: Failed | M38: Not implemented? | N38: Spec 6.3, Spec 9 (UI/UX) → "Statuses: Draft / Applying / Waiting for Approval (by stage) / Sent Back / Rejected / Approved / Expired."
A39: KT-ROL-001 | B39: User Role | C39: Staff sees own submissions | D39: Staff sees only own submissions on dashboard | E39: Main | F39: Multiple users have submissions | G39: 1. Login manager@gmail.com → submit ringi: 'Manager's Test Submission', Low, Management (if not already done) 2. Logout → login staff@gmail.com 3. Go to dashboard → check all visible submission cards | H39: Staff sees only OWN submissions. 'Manager's Test Submission' NOT visible. No other users' submissions. | I39: (none) | J39: P1 | K39: Partial Pass | L39: https://jam.dev/c/c778d93c-439e-47df-9600-95ef39426796 | M39: Client Side (FE side) Bug, after changin the role, the previous role submission still appear | N39: Spec 6.7 (Permissions), Spec 3 (Stakeholders) → "RBAC: Initiators edit/view their own applications, approvers operate on assigned cases, admins view all and change settings."
A40: KT-ROL-002 | B40: User Role | C40: Manager sees all + can approve | D40: Manager sees all submissions and can approve | E40: Main | F40: Submissions from multiple users exist | G40: 1. Login manager@gmail.com 2. Go to dashboard → check visible submission cards 3. Click any pending submission → detail /approval-requests/[id] 4. Check available action buttons | H40: Manager sees submissions from ALL users. Green Approve and red Reject buttons on pending submissions. | I40: (none) | J40: P1 | K40: Failed | M40: manager cannot see staff currently | N40: Spec 6.7 (Permissions), Spec 3 (Stakeholders) → "RBAC: Initiators edit/view their own applications, approvers operate on assigned cases, admins view all and change settings."
...

Sheet テストケース
A1: テストケースID | B1: カテゴリ | C1: 機能 | D1: テストケースタイトル | E1: 前提条件 | F1: テスト手順 | G1: 期待結果 | H1: 優先度 | I1: 実装状況 | J1: 備考 | K1: URL | L1: 合否 | M1: リンク | N1: 備考 | O1: 仕様書参照
A2: TC-SUB-001 | B2: 申請 | C2: フォーム項目 | D2: 全必須項目を入力して稟議を申請 | E2: 従業員としてログイン済み | F2: 1. アプリURLに移動する 2. 「新規申請」ボタンをクリック 3. タイトルを入力: 'Office Supplies Purchase' 4. カテゴリを選択: 'Purchasing' 5. 取引先名を入力: 'ABC Corp' 6. 項目を追加: Name='Printer', Qty=2, Amount=50000 7. 優先度を選択: 'High' 8. 期限日を設定 9. 部門を入力: 'Engineering' 10. 購入理由を入力 11. 目的を入力 12. 「送信」をクリック | G2: ステータス「保留中」で稟議が作成される. ダッシュボードにカードが表示される. アクティビティログに作成が記録される. | H2: P1 | I2: 実装済み | J2: 現在のフォーム項目で基本的な申請フローが動作 | K2: https://eb-filemg-development.vercel.app | L2: N/A | O2: Spec 6.1 (申請) → "フォーム項目: Subject, Category (Purchasing, Contracts, Expenses, Misc.), Amount (tax incl./excl.), Tax category, Payment terms, Vendor/Counterparty, Purpose, Period, Budget code, Project, Desired approval date, Applicant/Department."
A3: TC-SUB-002 | B3: 申請 | C3: 税計算 | D3: 税込計算で稟議を申請 | E3: ログイン済み、カテゴリは購買 | F3: 1. 「新規申請」をクリック 2. カテゴリを選択: 'Purchasing' 3. 「税金を使用」をONに切り替え 4. 「税込」に切り替え 5. 税率を入力: 10% 6. 項目を追加: Amount=110000 7. 残りの必須項目を入力 8. 「送信」をクリック | G3: 税金が正しく計算される. 金額が税込ラベルで表示される. 合計が税計算を反映する. | H3: P2 | I3: 実装済み | J3: 税金切替は購買カテゴリでのみ表示 | K3: https://eb-filemg-development.vercel.app | L3: N/A | O3: Spec 6.1 (申請) → "フォーム項目: Subject, Category (Purchasing, Contracts, Expenses, Misc.), Amount (tax incl./excl.), Tax category, Payment terms, Vendor/Counterparty, Purpose, Period, Budget code, Project, Desired approval date, Applicant/Department."
A4: TC-SUB-003 | B4: 申請 | C4: 税計算 | D4: 税抜計算で稟議を申請 | E4: ログイン済み、カテゴリは購買 | F4: 1. 「新規申請」をクリック 2. カテゴリを選択: 'Purchasing' 3. 「税金を使用」をONに切り替え 4. 「税抜」に切り替え 5. 税率を入力: 10% 6. 項目を追加: Amount=100000 7. 残りの必須項目を入力 8. 「送信」をクリック | G4: Tax calculated on top of amount. 税抜金額 + 税 = 合計が表示される. | H4: P2 | I4: 実装済み | J4: 税抜は基本金額に税金を加算 | K4: https://eb-filemg-development.vercel.app | L4: N/A | O4: Spec 6.1 (申請) → "フォーム項目: Subject, Category (Purchasing, Contracts, Expenses, Misc.), Amount (tax incl./excl.), Tax category, Payment terms, Vendor/Counterparty, Purpose, Period, Budget code, Project, Desired approval date, Applicant/Department."
A5: TC-SUB-004 | B5: 申請 | C5: 明細項目 | D5: 複数明細項目で稟議を申請 | E5: ログイン済み | F5: 1. 「新規申請」をクリック 2. 必須項目を入力 3. 項目1を追加: 'Laptop', Qty=5, Amount=200000 4. 「項目追加」をクリック 5. 項目2を追加: 'Mouse', Qty=5, Amount=5000 6. 「項目追加」をクリック 7. 項目3を追加: 'Keyboard', Qty=5, Amount=8000 8. 合計が自動計算されることを確認 9. 「送信」をクリック | G5: 3つの項目すべてが保存される. Total amount = (200000x5 + 5000x5 + 8000x5) = 1,065,000. 詳細ページに項目テーブルが正しく表示される. | H5: P2 | I5: 実装済み | J5: 項目はJSONB配列として保存 | K5: https://eb-filemg-development.vercel.app | L5: N/A | O5: Spec 6.1 (申請) → "フォーム項目: Subject, Category (Purchasing, Contracts, Expenses, Misc.), Amount (tax incl./excl.), Tax category, Payment terms, Vendor/Counterparty, Purpose, Period, Budget code, Project, Desired approval date, Applicant/Department."
A6: TC-SUB-005 | B6: 申請 | C6: バリデーション | D6: 必須項目未入力で稟議を申請（バリデーション） | E6: ログイン済み | F6: 1. 「新規申請」をクリック 2. タイトルを空のままにする 3. 取引先名を空のままにする 4. 項目を追加しない 5. 「送信」をクリック | G6: 全必須項目にフォームバリデーションエラーが表示される. 申請がブロックされる. 現在の言語でエラーメッセージが表示される (EN/JA). | H6: P1 | I6: 実装済み | J6: Yupバリデーションスキーマが必須項目を強制 | K6: https://eb-filemg-development.vercel.app | L6: N/A | O6: Spec 6.1 (申請) → "フォーム項目: Subject, Category (Purchasing, Contracts, Expenses, Misc.), Amount (tax incl./excl.), Tax category, Payment terms, Vendor/Counterparty, Purpose, Period, Budget code, Project, Desired approval date, Applicant/Department."
A7: TC-SUB-006 | B7: 申請 | C7: 添付ファイル | D7: 書類添付付きで稟議を申請 | E7: ログイン済み、システムにドキュメントが存在 | F7: 1. 「新規申請」をクリック 2. 必須項目をすべて入力 3. In attachments section, upload a PDF file 4. 2つ目の画像ファイルをアップロード 5. 「送信」をクリック 6. に移動する detail page | G7: 両方の添付ファイルが稟議にリンクされる. 詳細ページにダウンロードリンク付きファイルカードが表示される. | H7: P2 | I7: 実装済み | J7: approval_request_documents結合テーブルを使用 | K7: https://eb-filemg-development.vercel.app | L7: N/A | O7: Spec 6.1 (申請) → "添付ファイル: Quotes, contracts, and related materials. 承認後の改ざん不可（新バージョンとして再申請が必要）."
A8: TC-SUB-008 | B8: 申請 | C8: フォーム項目 | D8: フォームに予算コード項目が存在するか確認 | E8: ログイン済み | F8: 1. 「新規申請」をクリック 2. を探す 'Budget Code' field in the form 3. 予算コードの値を入力 | G8: Budget Code 項目が存在し入力可能. 値が稟議と共に保存される. | H8: P3 | I8: 未実装 | J8: 仕様書セクション8にbudget_codeが必要。現在のスキーマにはない。 | K8: https://eb-filemg-development.vercel.app | L8: N/A | O8: Spec 6.1 (申請) → "フォーム項目: Subject, Category (Purchasing, Contracts, Expenses, Misc.), Amount (tax incl./excl.), Tax category, Payment terms, Vendor/Counterparty, Purpose, Period, Budget code, Project, Desired approval date, Applicant/Department."
A9: TC-SUB-009 | B9: 申請 | C9: フォーム項目 | D9: フォームにプロジェクトコード項目が存在するか確認 | E9: ログイン済み | F9: 1. 「新規申請」をクリック 2. を探す 'Project Code' field in the form 3. プロジェクトコードの値を入力 | G9: Project Code 項目が存在し入力可能. 値が稟議と共に保存される. | H9: P3 | I9: 未実装 | J9: 仕様書セクション8にproject_codeが必要。現在のスキーマにはない。 | K9: https://eb-filemg-development.vercel.app | L9: N/A | O9: Spec 6.1 (申請) → "フォーム項目: Subject, Category (Purchasing, Contracts, Expenses, Misc.), Amount (tax incl./excl.), Tax category, Payment terms, Vendor/Counterparty, Purpose, Period, Budget code, Project, Desired approval date, Applicant/Department."
A10: TC-SUB-010 | B10: 申請 | C10: フォーム項目 | D10: フォームに通貨項目が存在するか確認 | E10: ログイン済み | F10: 1. 「新規申請」をクリック 2. を探す 'Currency' selector in the form 3. 異なる通貨を選択 (JPY, USD, etc.) | G10: 通貨フィールドにオプション（JPY、USDなど）が存在。選択した通貨が稟議に保存される。 | H10: P3 | I10: 未実装 | J10: 仕様書セクション8にcurrencyが必要。現在のスキーマにはない。 | K10: https://eb-filemg-development.vercel.app | L10: N/A | O10: Spec 6.1 (申請) → "フォーム項目: Subject, Category (Purchasing, Contracts, Expenses, Misc.), Amount (tax incl./excl.), Tax category, Payment terms, Vendor/Counterparty, Purpose, Period, Budget code, Project, Desired approval date, Applicant/Department."
